[2019-04-28 23:49:45,341](INFO)werkzeug :  * Running on http://127.0.0.1:5000/ (Press CTRL+C to quit)
[2019-04-28 23:50:23,342](INFO)root : 获得参数dayOfWeek:Mon location:十教 code:071Y1Yjo1EO02j0UMXjo1s3Mjo1Y1Yjf
[2019-04-28 23:50:23,353](ERROR)flask.app : Exception on /deleteSelfLocation [POST]
Traceback (most recent call last):
  File "F:\healthyBreakfast\venv\lib\site-packages\urllib3\connection.py", line 159, in _new_conn
    (self._dns_host, self.port), self.timeout, **extra_kw)
  File "F:\healthyBreakfast\venv\lib\site-packages\urllib3\util\connection.py", line 57, in create_connection
    for res in socket.getaddrinfo(host, port, family, socket.SOCK_STREAM):
  File "C:\Users\kxxy\AppData\Local\Programs\Python\Python37\lib\socket.py", line 748, in getaddrinfo
    for res in _socket.getaddrinfo(host, port, family, type, proto, flags):
socket.gaierror: [Errno 11001] getaddrinfo failed

During handling of the above exception, another exception occurred:

Traceback (most recent call last):
  File "F:\healthyBreakfast\venv\lib\site-packages\urllib3\connectionpool.py", line 600, in urlopen
    chunked=chunked)
  File "F:\healthyBreakfast\venv\lib\site-packages\urllib3\connectionpool.py", line 343, in _make_request
    self._validate_conn(conn)
  File "F:\healthyBreakfast\venv\lib\site-packages\urllib3\connectionpool.py", line 839, in _validate_conn
    conn.connect()
  File "F:\healthyBreakfast\venv\lib\site-packages\urllib3\connection.py", line 301, in connect
    conn = self._new_conn()
  File "F:\healthyBreakfast\venv\lib\site-packages\urllib3\connection.py", line 168, in _new_conn
    self, "Failed to establish a new connection: %s" % e)
urllib3.exceptions.NewConnectionError: <urllib3.connection.VerifiedHTTPSConnection object at 0x000002A712A7C198>: Failed to establish a new connection: [Errno 11001] getaddrinfo failed

During handling of the above exception, another exception occurred:

Traceback (most recent call last):
  File "F:\healthyBreakfast\venv\lib\site-packages\requests\adapters.py", line 449, in send
    timeout=timeout
  File "F:\healthyBreakfast\venv\lib\site-packages\urllib3\connectionpool.py", line 638, in urlopen
    _stacktrace=sys.exc_info()[2])
  File "F:\healthyBreakfast\venv\lib\site-packages\urllib3\util\retry.py", line 399, in increment
    raise MaxRetryError(_pool, url, error or ResponseError(cause))
urllib3.exceptions.MaxRetryError: HTTPSConnectionPool(host='api.weixin.qq.com', port=443): Max retries exceeded with url: /sns/jscode2session?appid=wx944dabad67e2a749&secret=2a17c2ce3099eb9d710fd6dafd9432ab&js_code=071Y1Yjo1EO02j0UMXjo1s3Mjo1Y1Yjf&grant_type=authorization_code (Caused by NewConnectionError('<urllib3.connection.VerifiedHTTPSConnection object at 0x000002A712A7C198>: Failed to establish a new connection: [Errno 11001] getaddrinfo failed'))

During handling of the above exception, another exception occurred:

Traceback (most recent call last):
  File "F:\healthyBreakfast\venv\lib\site-packages\flask\app.py", line 2292, in wsgi_app
    response = self.full_dispatch_request()
  File "F:\healthyBreakfast\venv\lib\site-packages\flask\app.py", line 1815, in full_dispatch_request
    rv = self.handle_user_exception(e)
  File "F:\healthyBreakfast\venv\lib\site-packages\flask\app.py", line 1718, in handle_user_exception
    reraise(exc_type, exc_value, tb)
  File "F:\healthyBreakfast\venv\lib\site-packages\flask\_compat.py", line 35, in reraise
    raise value
  File "F:\healthyBreakfast\venv\lib\site-packages\flask\app.py", line 1813, in full_dispatch_request
    rv = self.dispatch_request()
  File "F:\healthyBreakfast\venv\lib\site-packages\flask\app.py", line 1799, in dispatch_request
    return self.view_functions[rule.endpoint](**req.view_args)
  File "F:/healthyBreakfast/local/selfLocation__1.py", line 70, in deleteSelfLocation
    thisOpenId = l_object.getOpenId()
  File "F:\healthyBreakfast\local\getOpenID.py", line 14, in getOpenId
    r = requests.get(url)
  File "F:\healthyBreakfast\venv\lib\site-packages\requests\api.py", line 75, in get
    return request('get', url, params=params, **kwargs)
  File "F:\healthyBreakfast\venv\lib\site-packages\requests\api.py", line 60, in request
    return session.request(method=method, url=url, **kwargs)
  File "F:\healthyBreakfast\venv\lib\site-packages\requests\sessions.py", line 533, in request
    resp = self.send(prep, **send_kwargs)
  File "F:\healthyBreakfast\venv\lib\site-packages\requests\sessions.py", line 646, in send
    r = adapter.send(request, **kwargs)
  File "F:\healthyBreakfast\venv\lib\site-packages\requests\adapters.py", line 516, in send
    raise ConnectionError(e, request=request)
requests.exceptions.ConnectionError: HTTPSConnectionPool(host='api.weixin.qq.com', port=443): Max retries exceeded with url: /sns/jscode2session?appid=wx944dabad67e2a749&secret=2a17c2ce3099eb9d710fd6dafd9432ab&js_code=071Y1Yjo1EO02j0UMXjo1s3Mjo1Y1Yjf&grant_type=authorization_code (Caused by NewConnectionError('<urllib3.connection.VerifiedHTTPSConnection object at 0x000002A712A7C198>: Failed to establish a new connection: [Errno 11001] getaddrinfo failed'))
[2019-04-28 23:50:23,374](INFO)werkzeug : 127.0.0.1 - - [28/Apr/2019 23:50:23] "POST /deleteSelfLocation?dayOfWeek=Mon&location=十教&code=071Y1Yjo1EO02j0UMXjo1s3Mjo1Y1Yjf HTTP/1.1" 500 -
[2019-04-28 23:53:18,612](INFO)root : 获得参数dayOfWeek:Mon location:十教 code:0817q17w0gu9ib12s87w0AVo7w07q17s
[2019-04-28 23:53:19,115](INFO)root : 换取openid成功
[2019-04-28 23:53:19,118](INFO)root : 执行sql：delete from selfLocation where openid = 'ogQH25SmMVHvcBInksg7NkNVYTF4' and dayofweek = 'Mon' and location = '十教'
[2019-04-28 23:53:19,118](INFO)root : 执行成功，返回200
[2019-04-28 23:53:19,119](INFO)werkzeug : 127.0.0.1 - - [28/Apr/2019 23:53:19] "POST /deleteSelfLocation?dayOfWeek=Mon&location=十教&code=0817q17w0gu9ib12s87w0AVo7w07q17s HTTP/1.1" 200 -
